test1 (file_manager.file_manager_module.hierarchy.tests.python_unittests.docker_image1.docker_image1) ... ok
test2 (file_manager.file_manager_module.hierarchy.tests.python_unittests.docker_image1.docker_image1) ... FAIL
test3 (file_manager.file_manager_module.hierarchy.tests.python_unittests.docker_image1.docker_image1) ... FAIL

======================================================================
FAIL: test2 (file_manager.file_manager_module.hierarchy.tests.python_unittests.docker_image1.docker_image1)
----------------------------------------------------------------------
Traceback (most recent call last):
  File "/Users/zaksakata/Desktop/Stuff/Coding Projects/python-test-environment/server/file_manager/file_manager_module/hierarchy/tests/python_unittests/docker_image1.py", line 35, in test2
    self.assertFalse(output_1)
AssertionError: b"On branch main\nYour branch is up to date with 'origin/main'.\n\nnothing to commit, working tree clean\n" is not false

======================================================================
FAIL: test3 (file_manager.file_manager_module.hierarchy.tests.python_unittests.docker_image1.docker_image1)
----------------------------------------------------------------------
Traceback (most recent call last):
  File "/Users/zaksakata/Desktop/Stuff/Coding Projects/python-test-environment/server/file_manager/file_manager_module/hierarchy/tests/python_unittests/docker_image1.py", line 25, in test3
    self.assertRegex(output_1.decode(), '/some_regex/g')
AssertionError: Regex didn't match: '/some_regex/g' not found in "remote: You are not allowed to upload code.\nfatal: unable to access 'https://gitlab.com/haydenlhannappel/python-test-environment.git/': The requested URL returned error: 403\n"

----------------------------------------------------------------------
Ran 3 tests in 13.361s

FAILED (failures=2)
