test1_1 (file_manager.file_manager_module.hierarchy.tests.python_unittests.docker_image1.docker_image1) ... ok
test1_2 (file_manager.file_manager_module.hierarchy.tests.python_unittests.docker_image1.docker_image1) ... ok
test2_1 (file_manager.file_manager_module.hierarchy.tests.python_unittests.docker_image1.docker_image1) ... ok
test2_2 (file_manager.file_manager_module.hierarchy.tests.python_unittests.docker_image1.docker_image1) ... FAIL
test2_3 (file_manager.file_manager_module.hierarchy.tests.python_unittests.docker_image1.docker_image1) ... FAIL
test3_1 (file_manager.file_manager_module.hierarchy.tests.python_unittests.docker_image1.docker_image1) ... ok
test3_2 (file_manager.file_manager_module.hierarchy.tests.python_unittests.docker_image1.docker_image1) ... FAIL

======================================================================
FAIL: test2_2 (file_manager.file_manager_module.hierarchy.tests.python_unittests.docker_image1.docker_image1)
----------------------------------------------------------------------
Traceback (most recent call last):
  File "C:\Users\Poppycop\gitprojects\python-test-environment\server\file_manager\file_manager_module\hierarchy\tests\python_unittests\docker_image1.py", line 34, in test2_2
AssertionError: b"On branch main\nYour branch is up to date with 'origin/main'.\n\nnothing to commit, working tree clean\n" is not false

======================================================================
FAIL: test2_3 (file_manager.file_manager_module.hierarchy.tests.python_unittests.docker_image1.docker_image1)
----------------------------------------------------------------------
Traceback (most recent call last):
  File "C:\Users\Poppycop\gitprojects\python-test-environment\server\file_manager\file_manager_module\hierarchy\tests\python_unittests\docker_image1.py", line 38, in test2_3
AssertionError: b'Already up to date.\n' is not false

======================================================================
FAIL: test3_2 (file_manager.file_manager_module.hierarchy.tests.python_unittests.docker_image1.docker_image1)
----------------------------------------------------------------------
Traceback (most recent call last):
  File "C:\Users\Poppycop\gitprojects\python-test-environment\server\file_manager\file_manager_module\hierarchy\tests\python_unittests\docker_image1.py", line 45, in test3_2
AssertionError: Regex didn't match: '/some_regex/g' not found in "remote: You are not allowed to upload code.\nfatal: unable to access 'https://gitlab.com/haydenlhannappel/python-test-environment.git/': The requested URL returned error: 403\n"

----------------------------------------------------------------------
Ran 7 tests in 12.453s

FAILED (failures=3)
