test3 (file_manager.file_manager_module.hierarchy.tests.python_unittests.docker_image2.docker_image2) ... FAIL

======================================================================
FAIL: test3 (file_manager.file_manager_module.hierarchy.tests.python_unittests.docker_image2.docker_image2)
----------------------------------------------------------------------
Traceback (most recent call last):
  File "/Users/zaksakata/Desktop/Stuff/Coding Projects/python-test-environment/server/file_manager/file_manager_module/hierarchy/tests/python_unittests/docker_image2.py", line 25, in test3
    self.assertRegex(output_1.decode(), '/some_regex/g')
AssertionError: Regex didn't match: '/some_regex/g' not found in "remote: You are not allowed to upload code.\nfatal: unable to access 'https://gitlab.com/haydenlhannappel/python-test-environment.git/': The requested URL returned error: 403\n"

----------------------------------------------------------------------
Ran 1 test in 10.462s

FAILED (failures=1)
